<?xml version="1.0"?>
<!--
  Thorp cannon with its tilt servo
-->

<robot name="Thorp" xmlns:xacro="http://ros.org/wiki/xacro">

  <!-- Emulate the servo as a box and the cannon core as a cylinder -->
  <joint name="cannon_servo_joint" type="fixed">
    <origin xyz="-0.009 -0.002 -0.0195" rpy="0.0 0.0 0.0"/>
    <parent link="arm_mount_link"/>
    <child link="cannon_servo_link"/>
  </joint>
  <link name="cannon_servo_link">
    <visual>
      <origin xyz="0.0 0.006 0.0" rpy="0.0 0.0 0.0"/>
      <geometry>
        <box size="0.022 0.022 0.012"/>
      </geometry>
      <material name="Black"/>
    </visual>
    <xacro:box_inertia length="0.022" width="0.022" height="0.012" mass="0.01"/>
    <!-- covered under the arm mount, so no need for collision -->
  </link>

  <joint name="cannon_joint" type="revolute">
    <axis xyz="0 -1 0"/>
    <limit effort="1.0" velocity="5.0" lower="${-M_PI/10}" upper="${+M_PI/10}"/>
    <!-- 300 degrees/s (specs say 600/s, but then I cannot see the cannon rotate in gazebo),
         limits: +/-18 degrees operational range (servo limits are +/-30 degrees, I think) -->
    <origin xyz="0.006 -0.015 0.0" rpy="0.0 0.0 0.0"/>
    <parent link="cannon_servo_link"/>
    <child link="cannon_shaft_link"/>
  </joint>
  <link name="cannon_shaft_link">
    <visual>
      <origin xyz="0.0 0.002 0.0" rpy="${+M_PI/2} 0.0 0.0"/>
      <geometry>
        <cylinder radius="0.002" length="0.016"/>
      </geometry>
      <material name="Black"/>
    </visual>
    <!-- very small and light, so we don't need collision and inertial -->
  </link>

  <joint name="cannon_shaft_joint" type="fixed">
    <origin xyz="0.0 -0.015 0.0" rpy="0.0 0.0 0.0"/>
    <parent link="cannon_shaft_link"/>
    <child link="cannon_link"/>
  </joint>
  <link name="cannon_link">
    <visual>
      <origin xyz="0.009 0.0 0.0" rpy="0.0 ${+M_PI/2} 0.0"/>
      <geometry>
        <cylinder radius="0.01" length="0.028"/>
      </geometry>
      <material name="Black"/>
    </visual>
    <collision>
      <origin xyz="0.019 0.0 0.0" rpy="0.0 ${+M_PI/2} 0.0"/>
      <geometry>
        <cylinder radius="0.01" length="0.066"/>
      </geometry>
    </collision>
    <xacro:box_inertia length="0.03" width="0.02" height="0.02" mass="0.01" x="0.01"/>
    <!-- should be a cylinder... but is very light to bother -->
  </link>

  <!-- Emulate the six cannon tubes with two cylinders, the second a bit smaller and transparent -->
  <xacro:macro name="cannon_tube" params="parent number y_loc z_loc">
    <joint name="cannon_tube${number}_joint" type="fixed">
      <origin xyz="0.035 ${y_loc} ${z_loc}"/>
      <parent link="${parent}"/>
      <child link="cannon_tube${number}_link"/>
    </joint>

    <link name="cannon_tube${number}_link">
      <visual>
        <origin xyz="0.0 0.0 0.0" rpy="0.0 ${+M_PI/2} 0.0"/>
        <geometry>
          <cylinder radius="0.0025" length="0.025"/>
        </geometry>
        <material name="Black"/>
      </visual>
    </link>

    <joint name="cannon_tube${number}_hollow_joint" type="fixed">
      <origin xyz="0.0351 ${y_loc} ${z_loc}"/>
      <parent link="${parent}"/>
      <child link="cannon_tube${number}_hollow_link"/>
    </joint>

    <link name="cannon_tube${number}_hollow_link">
      <visual>
        <origin xyz="0.0 0.0 0.0" rpy="0.0 ${+M_PI/2} 0.0"/>
        <geometry>
          <cylinder radius="0.0018" length="0.025"/>
        </geometry>
        <material name="transparent">
         <color rgb="0 0 0" alpha="0"/>
        </material>
      </visual>
    </link>
  </xacro:macro>

  <xacro:cannon_tube parent="cannon_link" number="1" y_loc=" 0.004400" z_loc=" 0.000000"/>
  <xacro:cannon_tube parent="cannon_link" number="2" y_loc=" 0.002200" z_loc=" 0.003811"/>
  <xacro:cannon_tube parent="cannon_link" number="3" y_loc="-0.002200" z_loc=" 0.003811"/>
  <xacro:cannon_tube parent="cannon_link" number="4" y_loc="-0.004400" z_loc=" 0.000000"/>
  <xacro:cannon_tube parent="cannon_link" number="5" y_loc="-0.002200" z_loc="-0.003811"/>
  <xacro:cannon_tube parent="cannon_link" number="6" y_loc=" 0.002200" z_loc="-0.003811"/>
</robot>